<robot name="cleaner">
    <material name="red"> <color rgba="0.6 0 0 1"/> </material>
    <material name="green"> <color rgba="0 0.6 0 1"/> </material>
    <material name="blue"> <color rgba="0 0 0.6 1"/> </material>
    <material name="gray"> <color rgba="0.6 0.6 0.6 1"/> </material>
    <material name="black"> <color rgba="0 0 0 1"/> </material>
    <material name="white"> <color rgba="1 1 1 1"/> </material>

    <link name="base_footprint"/>
    <joint name="base_footprint" type="fixed">
        <parent link="base_footprint"/>
        <child link="base_link"/>
        <origin xyz="0 0 0.015" rpy="0 0 0"/>
    </joint>

    <link name="base_link">
        <visual>
            <geometry>
                <box size="0.55 0.6 0.15"/>
            </geometry>
            <material name="white"/>
            <origin xyz="0 0 0.075" rpy="0 0 0"/>
        </visual>
    </link>


    <link name="left_wheel1">
        <visual>
            <geometry>
                <cylinder radius="0.09" length="0.025"/>
            </geometry>
            <material name="black"/>
            <origin xyz="0 0 0" rpy="0 0 0"/>
        </visual>
    </link>
    <joint name="left_wheel1_joint" type="continuous">
        <parent link="base_link"/>
        <child link="left_wheel1"/>
        <!-- 0.0125 teker uzunluk yarısı + 0.275 şase ucu + 0.0025 boşluk  -->
        <origin xyz="-0.29 0 0.075" rpy="0 1.57 3.14"/>
        <axis xyz="0 0 1"/>
    </joint>

    <link name="left_wheel2">
        <visual>
            <geometry>
                <cylinder radius="0.09" length="0.025"/>
            </geometry>
            <material name="black"/>
            <origin xyz="0 0 0" rpy="0 0 0"/>
        </visual>
    </link>
    <joint name="left_wheel2_joint" type="continuous">
        <parent link="base_link"/>
        <child link="left_wheel2"/>
        <!-- 0.0125 teker uzunluk yarısı + 0.275 şase ucu + 0.0025 boşluk  -->
        <origin xyz="-0.29 -0.2 0.075" rpy="0 1.57 3.14"/>
        <axis xyz="0 0 1"/>
    </joint>


    <link name="right_wheel1">
        <visual>
            <geometry>
                <cylinder radius="0.09" length="0.025"/>
            </geometry>
            <material name="black"/>
            <origin xyz="0 0 0" rpy="0 0 0"/>
        </visual>
    </link>
    <joint name="right_wheel1_joint" type="continuous">
        <parent link="base_link"/>
        <child link="right_wheel1"/>
        <!-- 0.0125 teker uzunluk yarısı + 0.275 şase ucu + 0.0025 boşluk  -->
        <origin xyz="0.29 0 0.075" rpy="0 1.57 0"/>
        <axis xyz="0 0 1"/>
    </joint>

    <link name="right_wheel2">
        <visual>
            <geometry>
                <cylinder radius="0.09" length="0.025"/>
            </geometry>
            <material name="black"/>
            <origin xyz="0 0 0" rpy="0 0 0"/>
        </visual>
    </link>
    <joint name="right_wheel2_joint" type="continuous">
        <parent link="base_link"/>
        <child link="right_wheel2"/>
        <!-- 0.0125 teker uzunluk yarısı + 0.275 şase ucu + 0.0025 boşluk  -->
        <origin xyz="0.29 -0.2 0.075" rpy="0 1.57 0"/>
        <axis xyz="0 0 1"/>
    </joint>

    <link name="brush">
        <visual>
            <geometry>
                <cylinder radius="0.3" length="0.1"/>
            </geometry>
            <material name="blue"/>
            <origin xyz="0 0 0" rpy="0 0 0"/>
        </visual>
    </link>

    <joint name="base_to_brush" type="continuous">
        <parent link="base_link"/>
        <child link="brush"/>
        <origin xyz="0 0.22 0.035" rpy="0 0 0"/>
        <axis xyz="0 0 1"/>
    </joint>

</robot>
